import logging
import re
import sys
import time
import unittest

from mock import patch, Mock
import pytest

import polling2


def is_py_34():
    """Returns True if the version of python running the tests is 3.4."""
    return sys.version_info.major == 3 and sys.version_info.minor == 4


def fib(n):
    """
    CPU intensive poor implementation of fib - to test multiprocessing backend
    kill
    """
    if n in [0,1]:
        return n
    return fib(n-1) + fib(n-2)


class TestPoll(object):

    def test_import(self):
        """Test that you can import via correct usage"""
        import polling2
        from polling2 import poll

        assert poll
        assert polling2

    def test_arg_no_arg(self):
        """Tests various permutations of calling with invalid args"""
        with pytest.raises(TypeError):
            polling2.poll()

    def test_arg_no_step(self):
        with pytest.raises(TypeError):
            polling2.poll(lambda: True)

    def test_no_poll_forever_or_maxtries(self):
        """No error raised without specifying poll_forever or a timeout/max_tries"""
        with pytest.raises(AssertionError):
            polling2.poll(lambda: True, step=1)

    def test_poll_forever_with_timeout_max_tries(self):
        with pytest.raises(AssertionError):
            polling2.poll(lambda: True, step=1, timeout=1, max_tries=1, poll_forever=True)

    def test_type_error_when_misspelt_argnames(self):
        with pytest.raises(TypeError):
            polling2.poll(target=lambda: None, step=2, timeout=10, check_sucess=lambda rv: rv is None)

    def test_valid_arg_options(self):
        # Valid options
        polling2.poll(lambda: True, step=1, poll_forever=True)
        polling2.poll(lambda: True, step=1, timeout=1)
        polling2.poll(lambda: True, step=1, max_tries=1)
        polling2.poll(lambda: True, step=1, timeout=1, max_tries=1)

    @patch('time.sleep', return_value=None)
    @patch('time.time', return_value=0)
    def test_timeout_exception(self, patch_sleep, patch_time):

        # Since the timeout is < 0, the first iteration of polling should raise the error if max timeout < 0
        try:
            polling2.poll(lambda: False, step=10, timeout=-1)
        except polling2.TimeoutException as e:
            assert e.values.qsize() == 1, 'There should have been 1 value pushed to the queue of values'
            assert e.last is False, 'The last value was incorrect'
        else:
            assert False, 'No timeout exception raised'

        # Test happy path timeout
        val = polling2.poll(lambda: True, step=0, timeout=0)
        assert val is True, 'Val was: {} != {}'.format(val, True)

    def test_max_call_exception(self):
        """
        Test that a MaxCallException will be raised 
        """
        tries = 100
        try:
            polling2.poll(lambda: False, step=0, max_tries=tries)
        except polling2.MaxCallException as e:
            assert e.values.qsize() == tries, 'Poll function called the incorrect number of times'
            assert e.last is False, 'The last value was incorrect'
        else:
            assert False, 'No MaxCallException raised'

    def test_max_call_no_sleep(self):
        """
        Test that a MaxCallException is raised without sleeping after the last call
        """
        tries = 2
        sleep = 0.1
        start_time = time.time()

        with pytest.raises(polling2.MaxCallException):
            polling2.poll(lambda: False, step=sleep, max_tries=tries)
        assert time.time() - start_time < tries * sleep, 'Poll function slept before MaxCallException'

    def test_ignore_specified_exceptions(self):
        """
        Test that ignore_exceptions tuple will ignore exceptions specified.
        Should throw any errors not in the tuple.
        """
        # raises_errors is a function that returns 3 different things, each time it is called.
        # First it raises a ValueError, then EOFError, then a TypeError.
        raises_errors = Mock(return_value=True, side_effect=[ValueError, EOFError, RuntimeError])
        with pytest.raises(RuntimeError):
            # We are ignoring the exceptions other than a TypeError.
            polling2.poll(target=raises_errors, step=0.1, max_tries=3,
                          ignore_exceptions=(ValueError, EOFError))
        assert raises_errors.call_count == 3

    def test_check_is_value(self):
        """
        Test that is_value() function can be used to create custom checkers.
        """
        result = polling2.poll(target=lambda: None, step=0.1, max_tries=1,
                               check_success=polling2.is_value(None))
        assert result is None
        result = polling2.poll(target=lambda: False, step=0.1, max_tries=1,
                               check_success=polling2.is_value(False))
        assert result is False
        result = polling2.poll(target=lambda: 123, step=0.1, max_tries=1,
                               check_success=polling2.is_value(123))
        assert result is 123
        with pytest.raises(polling2.MaxCallException):
            polling2.poll(target=lambda: 123, step=0.1, max_tries=1,
                          check_success=polling2.is_value(444))


    def test_multiprocessing(self):
        """
        Test multiprocessing backend poll with per_attempt_timeout set
        for a CPU intensive function
        """
        with pytest.raises(polling2.MaxCallException):
            polling2.poll(target=fib, args=(100,),
                          step=0.1, max_tries=1, backend='multiprocessing',
                          check_success = lambda x: x is None, per_attempt_timeout=1)



@pytest.mark.skipif(is_py_34(), reason="pytest logcap fixture isn't available on 3.4")
class TestPollLogging(object):

    def test_logs_call(self, caplog):
        """
        Test that basic information about the call to poll() is always logged.
        """
        with caplog.at_level(logging.DEBUG):
            polling2.poll(target=lambda: True, step=0.1, max_tries=1)
            assert len(caplog.records) == 1, "Should only be one log record."
            record = caplog.records[0]
            assert record.levelname == 'DEBUG'
            pattern = r"""
                        # Note, in verbose mode, need to explicitly include whitespace
                        # by putting blackslash in front of anywhere there should be whitespace.
                        Begin\ poll\(
                        target=<function.*<lambda>\ at\ 0x[0-9A-Za-z]+>,  # contains pointer to the function.
                        \ step=0\.1,
                        \ timeout=None,
                        \ max_tries=1,
                        \ poll_forever=False
                        \)
                    """
            # Assert we have a match, which means the record is like the regular expression.
            assert re.search(pattern=pattern, string=record.message, flags=re.VERBOSE)

    def test_logs_response_at_debug(self, caplog):
        """
        Test that the log_value decorator will log values returned to a check_success function.
        """
        with caplog.at_level(logging.DEBUG):
            polling2.poll(target=lambda: True, step=0.1, max_tries=1, log=logging.DEBUG)
            assert len(caplog.records) == 2, "Should only be two log records."
            record = caplog.records[1]
            assert record.levelname == 'DEBUG'
            assert record.message == "poll() calls check_success(True)"

    def test_logs_response_change_level(self, caplog):
        """
        Test that the log parameter controls the logging level in poll function
        """
        with caplog.at_level(logging.DEBUG):
            polling2.poll(target=lambda: True, step=0.1, max_tries=1, log=logging.INFO)
            assert len(caplog.records) == 2, "Should only be two log record."
            record = caplog.records[1]
            assert record.levelname == 'INFO'
            assert record.message == "poll() calls check_success(True)"

    def test_default_is_not_log(self, caplog):
        """
        Shouldn't log anything unless explicitly asked to do so. Except for Begin poll()
        """
        with caplog.at_level(logging.DEBUG):
            polling2.poll(target=lambda: True, step=0.1, max_tries=1)
            assert len(caplog.records) == 1, "Should ony be one log records"
            assert 'Begin poll(' in caplog.records[0].msg

    def test_log_error_default_is_not_log(self, caplog):
        """
        Shouldn't log anything unless explicitly asked to do so. Except for Begin poll()
        """
        raises_errors = Mock(side_effect=ValueError('msg is this'))
        with caplog.at_level(logging.DEBUG), pytest.raises(polling2.MaxCallException):
            polling2.poll(target=raises_errors, ignore_exceptions=(ValueError),
                          step=0.1, max_tries=2)
            assert len(caplog.records) == 1, "Wrong number of log records."
            # Test that logging.NOTSET does not print log records either.
            polling2.poll(target=raises_errors, ignore_exceptions=(ValueError),
                          step=0.1, max_tries=2, log_error=logging.NOTSET)
            assert len(caplog.records) == 2, "Wrong number of log records."

    def test_log_error_set_at_debug_level(self, caplog):
        """
        Test that when the log_error parameter is set to debug level, the ignored
        errors are sent to the logger.
        """
        raises_errors = Mock(side_effect=[ValueError('msg this'), RuntimeError('this msg')])
        with caplog.at_level(logging.DEBUG), pytest.raises(polling2.MaxCallException):
            polling2.poll(target=raises_errors, ignore_exceptions=(ValueError, RuntimeError),
                          step=0.1, max_tries=2, log_error=logging.DEBUG)
        assert len(caplog.records) == 3, "Wrong number of log records."
        assert caplog.records[1].message == "poll() ignored exception ValueError('msg this',)"
        assert caplog.records[2].message == "poll() ignored exception RuntimeError('this msg',)"
